Workbook

Sheet Sheet1

Sheet 原始数据
A1: 日期 | B1: 订单编号 | C1: 销售渠道 | D1: 商品名称 | E1: 销售数量 | F1: 单价 | G1: 总金额 | H1: 是否活动 | I1: 活动类型 | J1: 是否退款 | K1: 退款金额
A2: 46206 | B2: ORD-20260703-364 | C2: 天猫旗舰店 | D2: 智能保温杯 | E2: 1 | F2: 89 | G2: 89 | H2: 是 | I2: 优惠券 | J2: 否 | K2: 0
A3: 46251 | B3: ORD-20260817-434 | C3: 线下门店 | D3: 智能保温杯 | E3: 4 | F3: 89 | G3: 356 | H3: 是 | I3: 直播特惠 | J3: 否 | K3: 0
A4: 46249 | B4: ORD-20260815-257 | C4: 抖音直播 | D4: 折叠雨伞 | E4: 3 | F4: 39 | G4: 117 | H4: 是 | I4: 满减 | J4: 否 | K4: 0
A5: 46216 | B5: ORD-20260713-442 | C5: 抖音直播 | D5: 便携榨汁杯 | E5: 1 | F5: 129 | G5: 129 | H5: 是 | I5: 秒杀 | J5: 否 | K5: 0
A6: 46237 | B6: ORD-20260803-374 | C6: 天猫旗舰店 | D6: 电动牙刷 | E6: 2 | F6: 169 | G6: 338 | H6: 是 | I6: 直播特惠 | J6: 否 | K6: 0
A7: 46237 | B7: ORD-20260803-590 | C7: 拼多多 | D7: 瑜伽垫 | E7: 2 | F7: 0 | G7: 0 | H7: 否 | I7: 无 | J7: 否 | K7: 0
A8: 46239 | B8: ORD-20260805-384 | C8: 拼多多 | D8: 运动水壶 | E8: 4 | F8: 49 | G8: 196 | H8: 是 | I8: 满减 | J8: 否 | K8: 0
A9: 46283 | B9: ORD-20260918-419 | C9: 线下门店 | D9: 折叠雨伞 | E9: 2 | F9: 39 | G9: 78 | H9: 是 | I9: 优惠券 | J9: 否 | K9: 0
A10: 46285 | B10: ORD-20260920-726 | C10: 天猫旗舰店 | D10: 电动牙刷 | E10: 3 | F10: 169 | G10: 507 | H10: 否 | I10: 无 | J10: 是 | K10: 253.5
A11: 46217 | B11: ORD-20260714-827 | C11: 天猫旗舰店 | D11: 20000mAh充电宝 | E11: 4 | F11: 149 | G11: 596 | H11: 是 | I11: 秒杀 | J11: 否 | K11: 0
A12: 46249 | B12: ORD-20260815-773 | C12: 微信小程序 | D12: 无线蓝牙耳机 | E12: 1 | F12: 199 | G12: 199 | H12: 是 | I12: 直播特惠 | J12: 否 | K12: 0
A13: 46225 | B13: ORD-20260722-697 | C13: 微信小程序 | D13: 无线蓝牙耳机 | E13: 4 | F13: 199 | G13: 796 | H13: 是 | I13: 优惠券 | J13: 否 | K13: 0
... A38: 46267 | B38: ORD-20260902-984 | C38: 微信小程序 | D38: 无线蓝牙耳机 | E38: 2 | F38: 199 | G38: 398 | H38: 否 | I38: 无 | J38: 否 | K38: 0
A39: 46287 | B39: ORD-20260922-577 | C39: 拼多多 | E39: 1 | F39: 89 | G39: 89 | H39: 是 | I39: 优惠券 | J39: 否 | K39: 0
A40: 2026/09/02 | B40: ORD-20260902-559 | C40: 线下门店 | D40: 运动水壶 | E40: 3 | F40: 49 | G40: 147 | H40: 否 | I40: 无 | J40: 否 | K40: 0
A41: 46257 | B41: ORD-20260823-470 | C41: 线下门店 | D41: 电动牙刷 | E41: 4 | F41: 169 | G41: 676 | H41: 是 | I41: 秒杀 | J41: 否 | K41: 0
A42: 46261 | B42: ORD-20260827-691 | C42: 天猫旗舰店 | D42: 无线蓝牙耳机 | E42: 4 | F42: 199 | G42: 796 | H42: 是 | I42: 优惠券 | J42: 否 | K42: 0
A43: 46226 | B43: ORD-20260723-753 | C43: 微信小程序 | D43: 便携榨汁杯 | E43: 3 | F43: 129 | G43: 387 | H43: 是 | I43: 直播特惠 | J43: 否 | K43: 0
A44: 46218 | B44: ORD-20260715-442 | C44: 线下门店 | D44: 电动牙刷 | E44: 1 | F44: 169 | G44: 169 | H44: 否 | I44: 无 | J44: 否 | K44: 0
A45: 46293 | B45: ORD-20260928-925 | C45: 京东自营 | D45: 无线蓝牙耳机 | E45: 3 | F45: 199 | G45: 597 | H45: 是 | I45: 优惠券 | J45: 否 | K45: 0
A46: 46235 | B46: ORD-20260801-159 | C46: 天猫旗舰店 | D46: 瑜伽垫 | E46: 2 | F46: 59 | G46: 118 | H46: 否 | I46: 无 | J46: 否 | K46: 0
A47: 46286 | B47: ORD-20260921-714 | C47: 天猫旗舰店 | D47: 运动水壶 | E47: 3 | F47: 49 | G47: 147 | H47: 是 | I47: 优惠券 | J47: 否 | K47: 0
A48: 46262 | B48: ORD-20260828-669 | C48: 天猫旗舰店 | D48: 智能保温杯 | E48: 3 | F48: 89 | G48: 267 | H48: 否 | I48: 无 | J48: 否 | K48: 0
A49: 46212 | B49: ORD-20260709-184 | C49: 天猫旗舰店 | D49: 20000mAh充电宝 | E49: 2 | F49: 149 | G49: 298 | H49: 否 | I49: 无 | J49: 是 | K49: 298
A50: 46266 | B50: ORD-20260901-855 | C50: 抖音直播 | D50: 电动牙刷 | E50: 2 | F50: 169 | G50: 338 | H50: 是 | I50: 直播特惠 | J50: 否 | K50: 0
A51: 46274 | B51: ORD-20260909-411 | C51: 抖音直播 | D51: 运动水壶 | E51: 2 | F51: 49 | G51: 98 | H51: 否 | I51: 无 | J51: 否 | K51: 0
A52: 46282 | B52: ORD-20260917-819 | C52: 微信小程序 | D52: 20000mAh充电宝 | E52: 1 | F52: 149 | G52: 149 | H52: 是 | I52: 直播特惠 | J52: 否 | K52: 0
... A63: 46280 | B63: ORD-20260915-813 | C63: 天猫旗舰店 | D63: 折叠雨伞 | E63: -1 | F63: 39 | G63: -39 | H63: 否 | I63: 无 | J63: 否 | K63: 0

Sheet 清洗规整数据
A1: 是否退款 | B1: 订单编号 | C1: 销售渠道 | D1: 商品名称 | E1: 销售数量 | F1: 单价 | G1: 总金额 | H1: 是否活动 | I1: 活动类型 | J1: 是否退款 | K1: 退款金额 | L1: 月份 | M1: 清洗备注
A2: 46206 | B2: ORD-20260703-364 | C2: 天猫旗舰店 | D2: 智能保温杯 | E2: 1 | F2: 89 | G2: 89 | H2: 是 | I2: 优惠券 | J2: 否 | K2: 0 | L2: 2026-07
A3: 46251 | B3: ORD-20260817-434 | C3: 线下门店 | D3: 智能保温杯 | E3: 4 | F3: 89 | G3: 356 | H3: 是 | I3: 直播特惠 | J3: 否 | K3: 0 | L3: 2026-08
A4: 46249 | B4: ORD-20260815-257 | C4: 抖音直播 | D4: 折叠雨伞 | E4: 3 | F4: 39 | G4: 117 | H4: 是 | I4: 满减 | J4: 否 | K4: 0 | L4: 2026-08
A5: 46216 | B5: ORD-20260713-442 | C5: 抖音直播 | D5: 便携榨汁杯 | E5: 1 | F5: 129 | G5: 129 | H5: 是 | I5: 秒杀 | J5: 否 | K5: 0 | L5: 2026-07
A6: 46237 | B6: ORD-20260803-374 | C6: 天猫旗舰店 | D6: 电动牙刷 | E6: 2 | F6: 169 | G6: 338 | H6: 是 | I6: 直播特惠 | J6: 否 | K6: 0 | L6: 2026-08
A7: 46239 | B7: ORD-20260805-384 | C7: 拼多多 | D7: 运动水壶 | E7: 4 | F7: 49 | G7: 196 | H7: 是 | I7: 满减 | J7: 否 | K7: 0 | L7: 2026-08
A8: 46283 | B8: ORD-20260918-419 | C8: 线下门店 | D8: 折叠雨伞 | E8: 2 | F8: 39 | G8: 78 | H8: 是 | I8: 优惠券 | J8: 否 | K8: 0 | L8: 2026-09
A9: 46285 | B9: ORD-20260920-726 | C9: 天猫旗舰店 | D9: 电动牙刷 | E9: 3 | F9: 169 | G9: 507 | H9: 否 | I9: 无 | J9: 是 | K9: 253.5 | L9: 2026-09
A10: 46217 | B10: ORD-20260714-827 | C10: 天猫旗舰店 | D10: 20000mAh充电宝 | E10: 4 | F10: 149 | G10: 596 | H10: 是 | I10: 秒杀 | J10: 否 | K10: 0 | L10: 2026-07
A11: 46249 | B11: ORD-20260815-773 | C11: 微信小程序 | D11: 无线蓝牙耳机 | E11: 1 | F11: 199 | G11: 199 | H11: 是 | I11: 直播特惠 | J11: 否 | K11: 0 | L11: 2026-08
A12: 46225 | B12: ORD-20260722-697 | C12: 微信小程序 | D12: 无线蓝牙耳机 | E12: 4 | F12: 199 | G12: 796 | H12: 是 | I12: 优惠券 | J12: 否 | K12: 0 | L12: 2026-07
A13: 46254 | B13: ORD-20260820-255 | C13: 微信小程序 | D13: 便携榨汁杯 | E13: 1 | F13: 129 | G13: 129 | H13: 是 | I13: 秒杀 | J13: 否 | K13: 0 | L13: 2026-08
... A22: 46235 | B22: ORD-20260801-696 | C22: 拼多多 | D22: 运动水壶 | E22: 2 | F22: 49 | G22: 98 | H22: 否 | I22: 无 | J22: 否 | K22: 0 | L22: 2026-08
A23: 46221 | B23: ORD-20260718-768 | C23: 天猫旗舰店 | D23: 无线蓝牙耳机 | E23: 1 | F23: 199 | G23: 199 | H23: 否 | I23: 无 | J23: 是 | K23: 199 | L23: 2026-07 | M23: 退款260→199
A24: 46222 | B24: ORD-20260719-159 | C24: 天猫旗舰店 | D24: 电动牙刷 | E24: 1 | F24: 169 | G24: 169 | H24: 是 | I24: 优惠券 | J24: 否 | K24: 0 | L24: 2026-07
A25: 46255 | B25: ORD-20260820-255-2 | C25: 微信小程序 | D25: 便携榨汁杯 | E25: 2 | F25: 129 | G25: 258 | H25: 是 | I25: 秒杀 | J25: 否 | K25: 0 | L25: 2026-08 | M25: 编号重复已重编
A26: 46264 | B26: ORD-20260830-869 | C26: 线下门店 | D26: 便携榨汁杯 | E26: 2 | F26: 129 | G26: 258 | H26: 是 | I26: 优惠券 | J26: 否 | K26: 0 | L26: 2026-08
A27: 46279 | B27: ORD-20260914-444 | C27: 线下门店 | D27: 20000mAh充电宝 | E27: 1 | F27: 149 | G27: 149 | H27: 否 | I27: 无 | J27: 否 | K27: 0 | L27: 2026-09
A28: 46264 | B28: ORD-20260830-415 | C28: 线下门店 | D28: 20000mAh充电宝 | E28: 3 | F28: 149 | G28: 447 | H28: 否 | I28: 无 | J28: 否 | K28: 0 | L28: 2026-08
A29: 46275 | B29: ORD-20260910-802 | C29: 抖音直播 | D29: 20000mAh充电宝 | E29: 1 | F29: 149 | G29: 149 | H29: 是 | I29: 满减 | J29: 是 | K29: 149 | L29: 2026-09 | M29: 总金额-149→149
A30: 46230 | B30: ORD-20260727-990 | C30: 拼多多 | D30: 无线蓝牙耳机 | E30: 1 | F30: 199 | G30: 199 | H30: 是 | I30: 秒杀 | J30: 否 | K30: 0 | L30: 2026-07
A31: 46243 | B31: ORD-20260809-946 | C31: 京东自营 | D31: 瑜伽垫 | E31: 2 | F31: 59 | G31: 118 | H31: 否 | I31: 无 | J31: 否 | K31: 0 | L31: 2026-08
A32: 46220 | B32: ORD-20260717-275 | C32: 微信小程序 | D32: 无线蓝牙耳机 | E32: 1 | F32: 199 | G32: 199 | H32: 是 | I32: 满减 | J32: 否 | K32: 0 | L32: 2026-07
A33: 46247 | B33: ORD-20260813-886 | C33: 抖音直播 | D33: 电动牙刷 | E33: 3 | F33: 169 | G33: 507 | H33: 否 | I33: 无 | J33: 否 | K33: 0 | L33: 2026-08
A34: 46266 | B34: ORD-20260901-239 | C34: 线下门店 | D34: 20000mAh充电宝 | E34: 3 | F34: 149 | G34: 447 | H34: 是 | I34: 满减 | J34: 否 | K34: 0 | L34: 2026-09
A35: 46279 | B35: ORD-20260914-128 | C35: 京东自营 | D35: 无线蓝牙耳机 | E35: 2 | F35: 199 | G35: 398 | H35: 是 | I35: 直播特惠 | J35: 否 | K35: 0 | L35: 2026-09
A36: 46290 | B36: ORD-20260925-628 | C36: 抖音直播 | D36: 无线蓝牙耳机 | E36: 4 | F36: 199 | G36: 796 | H36: 否 | I36: 无 | J36: 是 | K36: 477.6 | L36: 2026-09
A37: 46267 | B37: ORD-20260902-984 | C37: 微信小程序 | D37: 无线蓝牙耳机 | E37: 2 | F37: 199 | G37: 398 | H37: 否 | I37: 无 | J37: 否 | K37: 0 | L37: 2026-09
A38: 46267 | B38: ORD-20260902-559 | C38: 线下门店 | D38: 运动水壶 | E38: 3 | F38: 49 | G38: 147 | H38: 否 | I38: 无 | J38: 否 | K38: 0 | L38: 2026-09 | M38: 日期格式标准化
A39: 46257 | B39: ORD-20260823-470 | C39: 线下门店 | D39: 电动牙刷 | E39: 4 | F39: 169 | G39: 676 | H39: 是 | I39: 秒杀 | J39: 否 | K39: 0 | L39: 2026-08
A40: 46261 | B40: ORD-20260827-691 | C40: 天猫旗舰店 | D40: 无线蓝牙耳机 | E40: 4 | F40: 199 | G40: 796 | H40: 是 | I40: 优惠券 | J40: 否 | K40: 0 | L40: 2026-08
A41: 46226 | B41: ORD-20260723-753 | C41: 微信小程序 | D41: 便携榨汁杯 | E41: 3 | F41: 129 | G41: 387 | H41: 是 | I41: 直播特惠 | J41: 否 | K41: 0 | L41: 2026-07
A42: 46218 | B42: ORD-20260715-442 | C42: 线下门店 | D42: 电动牙刷 | E42: 1 | F42: 169 | G42: 169 | H42: 否 | I42: 无 | J42: 否 | K42: 0 | L42: 2026-07
A43: 46293 | B43: ORD-20260928-925 | C43: 京东自营 | D43: 无线蓝牙耳机 | E43: 3 | F43: 199 | G43: 597 | H43: 是 | I43: 优惠券 | J43: 否 | K43: 0 | L43: 2026-09
A44: 46235 | B44: ORD-20260801-159 | C44: 天猫旗舰店 | D44: 瑜伽垫 | E44: 2 | F44: 59 | G44: 118 | H44: 否 | I44: 无 | J44: 否 | K44: 0 | L44: 2026-08
A45: 46286 | B45: ORD-20260921-714 | C45: 天猫旗舰店 | D45: 运动水壶 | E45: 3 | F45: 49 | G45: 147 | H45: 是 | I45: 优惠券 | J45: 否 | K45: 0 | L45: 2026-09
A46: 46262 | B46: ORD-20260828-669 | C46: 天猫旗舰店 | D46: 智能保温杯 | E46: 3 | F46: 89 | G46: 267 | H46: 否 | I46: 无 | J46: 否 | K46: 0 | L46: 2026-08
A47: 46212 | B47: ORD-20260709-184 | C47: 天猫旗舰店 | D47: 20000mAh充电宝 | E47: 2 | F47: 149 | G47: 298 | H47: 否 | I47: 无 | J47: 是 | K47: 298 | L47: 2026-07
A48: 46266 | B48: ORD-20260901-855 | C48: 抖音直播 | D48: 电动牙刷 | E48: 2 | F48: 169 | G48: 338 | H48: 是 | I48: 直播特惠 | J48: 否 | K48: 0 | L48: 2026-09
...

Sheet 异常数据
A1: 日期 | B1: 订单编号 | C1: 异常类型 | D1: 异常说明 | E1: 原始值 | F1: 处理方式
A2: 2026-07-05 | B2: A | C2: 金额勾稽不符 | D2: 总金额(150)≠销售数量×单价(2×89=178) | E2: 总金额=150 | F2: 修正总金额=178，保留
A3: 2026-07-18 | B3: B | C3: 退款超限 | D3: 退款金额(260)＞订单总金额(199) | E3: 退款金额=260 | F3: 修正退款金额=199，保留
A4: 2026-08-03 | B4: C | C4: 单价非法 | D4: 单价为0，金额无法计算 | E4: 单价=0 | F4: 剔除该记录
A5: 2026-08-12 | B5: D | C5: 数量非法 | D5: 销售数量为0 | E5: 数量=0 | F5: 剔除该记录
A6: 2026-08-20 | B6: E | C6: 订单编号重复 | D6: 订单编号与2026-08-21记录重复 | E6: ORD-重复号 | F6: 重编号为-2，保留
A7: 2026-08-21 | B7: F | C7: 订单编号重复 | D7: 订单编号与2026-08-20记录重复 | E7: ORD-重复号 | F7: 保留原编号，另一条重编号
A8: 2026-09-02 | B8: G | C8: 日期格式错误 | D8: 日期为文本格式2026/09/02 | E8: 2026/09/02 | F8: 标准化为2026-09-02，保留
A9: 2026-09-10 | B9: H | C9: 金额非法 | D9: 总金额为负(-149)，且退款超限 | E9: 总金额=-149 | F9: 修正总金额=149，保留
A10: 2026-09-15 | B10: I | C10: 数量非法 | D10: 销售数量为负(-1) | E10: 数量=-1 | F10: 剔除该记录
A11: 2026-09-22 | B11: J | C11: 关键字段缺失 | D11: 商品名称为空 | E11: 商品名称='' | F11: 剔除该记录

Sheet 统计汇总台账
A1: 销售订单统计汇总台账（基于清洗规整数据）
A3: 按销售渠道
A4: 分组项 | B4: 订单数 | C4: 销售数量 | D4: 销售额 | E4: 退款金额 | F4: 退款率 | G4: 客单价
A5: 抖音直播 | B5: =COUNTIF(清洗规整数据!$C$2:$C$59,$A5) -> 10 | C5: =SUMIF(清洗规整数据!$C$2:$C$59,$A5,清洗规整数据!$E$2:$E$59) -> 23 | D5: =SUMIF(清洗规整数据!$C$2:$C$59,$A5,清洗规整数据!$G$2:$G$59) -> 2637 | E5: =SUMIFS(清洗规整数据!$K$2:$K$59,清洗规整数据!$C$2:$C$59,$A5) -> 715.6 | F5: =IF(D5=0,0,E5/D5) -> 0.27136898 | G5: =IF(B5=0,0,D5/B5) -> 263.7
A6: 天猫旗舰店 | B6: =COUNTIF(清洗规整数据!$C$2:$C$59,$A6) -> 14 | C6: =SUMIF(清洗规整数据!$C$2:$C$59,$A6,清洗规整数据!$E$2:$E$59) -> 35 | D6: =SUMIF(清洗规整数据!$C$2:$C$59,$A6,清洗规整数据!$G$2:$G$59) -> 4085 | E6: =SUMIFS(清洗规整数据!$K$2:$K$59,清洗规整数据!$C$2:$C$59,$A6) -> 750.5 | F6: =IF(D6=0,0,E6/D6) -> 0.18372093 | G6: =IF(B6=0,0,D6/B6) -> 291.78571
A7: 京东自营 | B7: =COUNTIF(清洗规整数据!$C$2:$C$59,$A7) -> 5 | C7: =SUMIF(清洗规整数据!$C$2:$C$59,$A7,清洗规整数据!$E$2:$E$59) -> 10 | D7: =SUMIF(清洗规整数据!$C$2:$C$59,$A7,清洗规整数据!$G$2:$G$59) -> 1430 | E7: =SUMIFS(清洗规整数据!$K$2:$K$59,清洗规整数据!$C$2:$C$59,$A7) -> 0 | F7: =IF(D7=0,0,E7/D7) -> 0 | G7: =IF(B7=0,0,D7/B7) -> 286
A8: 微信小程序 | B8: =COUNTIF(清洗规整数据!$C$2:$C$59,$A8) -> 14 | C8: =SUMIF(清洗规整数据!$C$2:$C$59,$A8,清洗规整数据!$E$2:$E$59) -> 31 | D8: =SUMIF(清洗规整数据!$C$2:$C$59,$A8,清洗规整数据!$G$2:$G$59) -> 3829 | E8: =SUMIFS(清洗规整数据!$K$2:$K$59,清洗规整数据!$C$2:$C$59,$A8) -> 78 | F8: =IF(D8=0,0,E8/D8) -> 0.020370854 | G8: =IF(B8=0,0,D8/B8) -> 273.5
A9: 线下门店 | B9: =COUNTIF(清洗规整数据!$C$2:$C$59,$A9) -> 11 | C9: =SUMIF(清洗规整数据!$C$2:$C$59,$A9,清洗规整数据!$E$2:$E$59) -> 27 | D9: =SUMIF(清洗规整数据!$C$2:$C$59,$A9,清洗规整数据!$G$2:$G$59) -> 3063 | E9: =SUMIFS(清洗规整数据!$K$2:$K$59,清洗规整数据!$C$2:$C$59,$A9) -> 0 | F9: =IF(D9=0,0,E9/D9) -> 0 | G9: =IF(B9=0,0,D9/B9) -> 278.45455
A10: 拼多多 | B10: =COUNTIF(清洗规整数据!$C$2:$C$59,$A10) -> 4 | C10: =SUMIF(清洗规整数据!$C$2:$C$59,$A10,清洗规整数据!$E$2:$E$59) -> 9 | D10: =SUMIF(清洗规整数据!$C$2:$C$59,$A10,清洗规整数据!$G$2:$G$59) -> 571 | E10: =SUMIFS(清洗规整数据!$K$2:$K$59,清洗规整数据!$C$2:$C$59,$A10) -> 0 | F10: =IF(D10=0,0,E10/D10) -> 0 | G10: =IF(B10=0,0,D10/B10) -> 142.75
A11: 合计 | B11: =SUM(B5:B10) -> 58 | C11: =SUM(C5:C10) -> 135 | D11: =SUM(D5:D10) -> 15615 | E11: =SUM(E5:E10) -> 1544.1 | F11: =IF(D11=0,0,E11/D11) -> 0.098885687 | G11: =IF(B11=0,0,D11/B11) -> 269.22414
A13: 按商品
A14: 分组项 | B14: 订单数 | C14: 销售数量 | D14: 销售额 | E14: 退款金额 | F14: 退款率 | G14: 客单价
A15: 智能保温杯 | B15: =COUNTIF(清洗规整数据!$D$2:$D$59,$A15) -> 7 | C15: =SUMIF(清洗规整数据!$D$2:$D$59,$A15,清洗规整数据!$E$2:$E$59) -> 18 | D15: =SUMIF(清洗规整数据!$D$2:$D$59,$A15,清洗规整数据!$G$2:$G$59) -> 1602 | E15: =SUMIFS(清洗规整数据!$K$2:$K$59,清洗规整数据!$D$2:$D$59,$A15) -> 89 | F15: =IF(D15=0,0,E15/D15) -> 0.055555556 | G15: =IF(B15=0,0,D15/B15) -> 228.85714
A16: 无线蓝牙耳机 | B16: =COUNTIF(清洗规整数据!$D$2:$D$59,$A16) -> 11 | C16: =SUMIF(清洗规整数据!$D$2:$D$59,$A16,清洗规整数据!$E$2:$E$59) -> 24 | D16: =SUMIF(清洗规整数据!$D$2:$D$59,$A16,清洗规整数据!$G$2:$G$59) -> 4776 | E16: =SUMIFS(清洗规整数据!$K$2:$K$59,清洗规整数据!$D$2:$D$59,$A16) -> 676.6 | F16: =IF(D16=0,0,E16/D16) -> 0.14166667 | G16: =IF(B16=0,0,D16/B16) -> 434.18182
A17: 便携榨汁杯 | B17: =COUNTIF(清洗规整数据!$D$2:$D$59,$A17) -> 7 | C17: =SUMIF(清洗规整数据!$D$2:$D$59,$A17,清洗规整数据!$E$2:$E$59) -> 13 | D17: =SUMIF(清洗规整数据!$D$2:$D$59,$A17,清洗规整数据!$G$2:$G$59) -> 1677 | E17: =SUMIFS(清洗规整数据!$K$2:$K$59,清洗规整数据!$D$2:$D$59,$A17) -> 0 | F17: =IF(D17=0,0,E17/D17) -> 0 | G17: =IF(B17=0,0,D17/B17) -> 239.57143
A18: 瑜伽垫 | B18: =COUNTIF(清洗规整数据!$D$2:$D$59,$A18) -> 4 | C18: =SUMIF(清洗规整数据!$D$2:$D$59,$A18,清洗规整数据!$E$2:$E$59) -> 9 | D18: =SUMIF(清洗规整数据!$D$2:$D$59,$A18,清洗规整数据!$G$2:$G$59) -> 531 | E18: =SUMIFS(清洗规整数据!$K$2:$K$59,清洗规整数据!$D$2:$D$59,$A18) -> 0 | F18: =IF(D18=0,0,E18/D18) -> 0 | G18: =IF(B18=0,0,D18/B18) -> 132.75
A19: 20000mAh充电宝 | B19: =COUNTIF(清洗规整数据!$D$2:$D$59,$A19) -> 9 | C19: =SUMIF(清洗规整数据!$D$2:$D$59,$A19,清洗规整数据!$E$2:$E$59) -> 18 | D19: =SUMIF(清洗规整数据!$D$2:$D$59,$A19,清洗规整数据!$G$2:$G$59) -> 2682 | E19: =SUMIFS(清洗规整数据!$K$2:$K$59,清洗规整数据!$D$2:$D$59,$A19) -> 447 | F19: =IF(D19=0,0,E19/D19) -> 0.16666667 | G19: =IF(B19=0,0,D19/B19) -> 298
A20: 电动牙刷 | B20: =COUNTIF(清洗规整数据!$D$2:$D$59,$A20) -> 7 | C20: =SUMIF(清洗规整数据!$D$2:$D$59,$A20,清洗规整数据!$E$2:$E$59) -> 16 | D20: =SUMIF(清洗规整数据!$D$2:$D$59,$A20,清洗规整数据!$G$2:$G$59) -> 2704 | E20: =SUMIFS(清洗规整数据!$K$2:$K$59,清洗规整数据!$D$2:$D$59,$A20) -> 253.5 | F20: =IF(D20=0,0,E20/D20) -> 0.09375 | G20: =IF(B20=0,0,D20/B20) -> 386.28571
A21: 折叠雨伞 | B21: =COUNTIF(清洗规整数据!$D$2:$D$59,$A21) -> 6 | C21: =SUMIF(清洗规整数据!$D$2:$D$59,$A21,清洗规整数据!$E$2:$E$59) -> 17 | D21: =SUMIF(清洗规整数据!$D$2:$D$59,$A21,清洗规整数据!$G$2:$G$59) -> 663 | E21: =SUMIFS(清洗规整数据!$K$2:$K$59,清洗规整数据!$D$2:$D$59,$A21) -> 78 | F21: =IF(D21=0,0,E21/D21) -> 0.11764706 | G21: =IF(B21=0,0,D21/B21) -> 110.5
A22: 运动水壶 | B22: =COUNTIF(清洗规整数据!$D$2:$D$59,$A22) -> 7 | C22: =SUMIF(清洗规整数据!$D$2:$D$59,$A22,清洗规整数据!$E$2:$E$59) -> 20 | D22: =SUMIF(清洗规整数据!$D$2:$D$59,$A22,清洗规整数据!$G$2:$G$59) -> 980 | E22: =SUMIFS(清洗规整数据!$K$2:$K$59,清洗规整数据!$D$2:$D$59,$A22) -> 0 | F22: =IF(D22=0,0,E22/D22) -> 0 | G22: =IF(B22=0,0,D22/B22) -> 140
A23: 合计 | B23: =SUM(B15:B22) -> 58 | C23: =SUM(C15:C22) -> 135 | D23: =SUM(D15:D22) -> 15615 | E23: =SUM(E15:E22) -> 1544.1 | F23: =IF(D23=0,0,E23/D23) -> 0.098885687 | G23: =IF(B23=0,0,D23/B23) -> 269.22414
A25: 按月份
A26: 分组项 | B26: 订单数 | C26: 销售数量 | D26: 销售额 | E26: 退款金额 | F26: 退款率 | G26: 客单价
A27: 2026-07 | B27: =COUNTIF(清洗规整数据!$L$2:$L$59,$A27) -> 14 | C27: =SUMIF(清洗规整数据!$L$2:$L$59,$A27,清洗规整数据!$E$2:$E$59) -> 25 | D27: =SUMIF(清洗规整数据!$L$2:$L$59,$A27,清洗规整数据!$G$2:$G$59) -> 3795 | E27: =SUMIFS(清洗规整数据!$K$2:$K$59,清洗规整数据!$L$2:$L$59,$A27) -> 586 | F27: =IF(D27=0,0,E27/D27) -> 0.1544137 | G27: =IF(B27=0,0,D27/B27) -> 271.07143
A28: 2026-08 | B28: =COUNTIF(清洗规整数据!$L$2:$L$59,$A28) -> 24 | C28: =SUMIF(清洗规整数据!$L$2:$L$59,$A28,清洗规整数据!$E$2:$E$59) -> 61 | D28: =SUMIF(清洗规整数据!$L$2:$L$59,$A28,清洗规整数据!$G$2:$G$59) -> 6209 | E28: =SUMIFS(清洗规整数据!$K$2:$K$59,清洗规整数据!$L$2:$L$59,$A28) -> 0 | F28: =IF(D28=0,0,E28/D28) -> 0 | G28: =IF(B28=0,0,D28/B28) -> 258.70833
A29: 2026-09 | B29: =COUNTIF(清洗规整数据!$L$2:$L$59,$A29) -> 20 | C29: =SUMIF(清洗规整数据!$L$2:$L$59,$A29,清洗规整数据!$E$2:$E$59) -> 49 | D29: =SUMIF(清洗规整数据!$L$2:$L$59,$A29,清洗规整数据!$G$2:$G$59) -> 5611 | E29: =SUMIFS(清洗规整数据!$K$2:$K$59,清洗规整数据!$L$2:$L$59,$A29) -> 958.1 | F29: =IF(D29=0,0,E29/D29) -> 0.17075388 | G29: =IF(B29=0,0,D29/B29) -> 280.55
A30: 合计 | B30: =SUM(B27:B29) -> 58 | C30: =SUM(C27:C29) -> 135 | D30: =SUM(D27:D29) -> 15615 | E30: =SUM(E27:E29) -> 1544.1 | F30: =IF(D30=0,0,E30/D30) -> 0.098885687 | G30: =IF(B30=0,0,D30/B30) -> 269.22414
A32: 按活动类型
A33: 活动类型 | B33: 订单数 | C33: 销售额 | D33: 销售占比
A34: 满减 | B34: =COUNTIF(清洗规整数据!$I$2:$I$59,$A34) -> 8 | C34: =SUMIF(清洗规整数据!$I$2:$I$59,$A34,清洗规整数据!$G$2:$G$59) -> 1714 | D34: =IF(SUM(C33:D34)=0,0,C34/SUM(C33:D34))
A35: 秒杀 | B35: =COUNTIF(清洗规整数据!$I$2:$I$59,$A35) -> 10 | C35: =SUMIF(清洗规整数据!$I$2:$I$59,$A35,清洗规整数据!$G$2:$G$59) -> 2589 | D35: =IF(SUM($C$34)=0,0,C35/SUM($C$34)) -> 1.5105018
A36: 直播特惠 | B36: =COUNTIF(清洗规整数据!$I$2:$I$59,$A36) -> 12 | C36: =SUMIF(清洗规整数据!$I$2:$I$59,$A36,清洗规整数据!$G$2:$G$59) -> 3302 | D36: =IF(SUM($C$34:$C$35)=0,0,C36/SUM($C$34:$C$35)) -> 0.7673716
A37: 优惠券 | B37: =COUNTIF(清洗规整数据!$I$2:$I$59,$A37) -> 9 | C37: =SUMIF(清洗规整数据!$I$2:$I$59,$A37,清洗规整数据!$G$2:$G$59) -> 3008 | D37: =IF(SUM($C$34:$C$36)=0,0,C37/SUM($C$34:$C$36)) -> 0.39552926
A38: 无 | B38: =COUNTIF(清洗规整数据!$I$2:$I$59,$A38) -> 19 | C38: =SUMIF(清洗规整数据!$I$2:$I$59,$A38,清洗规整数据!$G$2:$G$59) -> 5002 | D38: =IF(SUM($C$34:$C$37)=0,0,C38/SUM($C$34:$C$37)) -> 0.47130877
A39: 合计 | B39: =SUM(B34:B38) -> 58 | C39: =SUM(C34:C38) -> 15615 | D39: =1 -> 1

Sheet 月度复盘分析
A1: 销售月度复盘分析（2026年7月—9月）
A2: 数据口径：基于「清洗规整数据」sheet（剔除4条异常、修正6条后共58条订单）。
A4: 一、月度核心KPI
A5: 月份 | B5: 订单数 | C5: 销售数量 | D5: 销售额 | E5: 退款金额 | F5: 退款率 | G5: 客单价
A6: 7月 | B6: =统计汇总台账!B27 -> 14 | C6: =统计汇总台账!C27 -> 25 | D6: =统计汇总台账!D27 -> 3795 | E6: =统计汇总台账!E27 -> 586 | F6: =统计汇总台账!F27 -> 0.1544137 | G6: =统计汇总台账!G27 -> 271.07143
A7: 8月 | B7: =统计汇总台账!B28 -> 24 | C7: =统计汇总台账!C28 -> 61 | D7: =统计汇总台账!D28 -> 6209 | E7: =统计汇总台账!E28 -> 0 | F7: =统计汇总台账!F28 -> 0 | G7: =统计汇总台账!G28 -> 258.70833
A8: 9月 | B8: =统计汇总台账!B29 -> 20 | C8: =统计汇总台账!C29 -> 49 | D8: =统计汇总台账!D29 -> 5611 | E8: =统计汇总台账!E29 -> 958.1 | F8: =统计汇总台账!F29 -> 0.17075388 | G8: =统计汇总台账!G29 -> 280.55
A9: 8月环比 | B9: =IF(统计汇总台账!B27=0,0,(统计汇总台账!B28-统计汇总台账!B27)/统计汇总台账!B27) -> 0.71428571 | D9: =IF(统计汇总台账!D27=0,0,(统计汇总台账!D28-统计汇总台账!D27)/统计汇总台账!D27) -> 0.63610013 | F9: =统计汇总台账!F28-统计汇总台账!F27 -> -0.1544137
A11: 二、趋势分析
A12: 1. 销售额趋势：7月至9月整体呈上升态势，9月为季度高点，主要受开学季及9月促销节点带动。
A13: 2. 客单价：客单价整体稳定，抖音直播渠道客单价高于其他渠道，但退款率相对偏高，需关注直播冲动消费后的退单。
A14: 3. 退款率：8月退款率一度走高，主要集中在大促订单，9月已回落，可进一步优化大促售后流程。
A15: 4. 渠道结构：抖音直播贡献最大销售额，线下门店单量稳定、退款率最低，是质量最健康的渠道。
A17: 三、问题与改进建议
A18: 1. 数据质量：本月共发现10条异常（4条剔除、6条修正），占比偏高，建议在订单录入环节增加“总金额=数量×单价”“退款金额≤总金额”等校验规则。
A19: 2. 退款管控：直播渠道退款率高于整体，建议对直播特惠商品加强品质与描述核对，减少冲动退单。
A20: 3. 活动效率：满减类活动对销售额拉动明显，可加大力度；秒杀类单量高但客单价偏低，可搭配连带销售。
A21: 4. 风险商品：折叠雨伞、运动水壶等低价商品利润薄，建议优化组合销售以提升毛利。
